#VRML_SIM R2025a utf8

EXTERNPROTO "https://raw.githubusercontent.com/cyberbotics/webots/R2023a/projects/objects/backgrounds/protos/TexturedBackground.proto"
EXTERNPROTO "https://raw.githubusercontent.com/cyberbotics/webots/R2023a/projects/objects/backgrounds/protos/TexturedBackgroundLight.proto"
EXTERNPROTO "https://raw.githubusercontent.com/cyberbotics/webots/R2025a/projects/objects/toys/protos/RubberDuck.proto"
EXTERNPROTO "https://raw.githubusercontent.com/cyberbotics/webots/R2025a/projects/objects/balls/protos/FifaSoccerBall.proto"
EXTERNPROTO "https://raw.githubusercontent.com/cyberbotics/webots/R2025a/projects/objects/apartment_structure/protos/Wall.proto"
EXTERNPROTO "https://raw.githubusercontent.com/cyberbotics/webots/R2025a/projects/objects/robotstadium/protos/RobotstadiumSoccerField.proto"

WorldInfo {
}
Viewpoint {
  orientation 0.0973318624345897 -0.5614340140899329 -0.8217775589403004 5.867331535592887
  position -4.5293448047532125 -1.8659609223984355 1.3091045891377264
}
TexturedBackground {
}
TexturedBackgroundLight {
}
FifaSoccerBall {
  translation 3.48 -0.13 0.0596782
  size 1
}
RubberDuck {
  translation 0.61 -1.07 0.020438
  rotation -2.16364e-17 2.33322e-17 1 3.14159
}
Robot {
  translation -1.69762 -0.259435 -0.0184427
  rotation -0.019544124113652233 -0.018267055721983706 0.9996421069002046 1.511260511308513
  children [
    Camera {
      translation 3.9793e-08 -0.037 0.1
      rotation 0 0 -1 1.5708003061004252
      children [
        Pose {
          translation 0.0043 0.0015 0
          children [
            Shape {
              appearance PBRAppearance {
                baseColor 0.843137 0.792157 0.231373
                roughness 1
                metalness 0.3
              }
              geometry Box {
                size 0.01 0.01 0.02
              }
            }
          ]
        }
      ]
      fieldOfView 0.7
      width 256
      height 128
      antiAliasing TRUE
    }
    HingeJoint {
      jointParameters HingeJointParameters {
        position 40.63240649134448
        anchor 0.045 0 0.048
      }
      device [
        PositionSensor {
          name "left wheel sensor"
        }
        RotationalMotor {
          name "left_motor"
        }
      ]
      endPoint Solid {
        translation 1.4095994761015307e-07 0.009920187603812 0.09498580479777569
        rotation -0.9999999999998276 4.2806639043050087e-07 4.0223491684531857e-07 3.3498906871907983
        children [
          DEF wheel Pose {
            translation 0.044992 0 0.048
            rotation 0 1 0 1.57
            children [
              Shape {
                appearance PBRAppearance {
                  baseColor 0.682353 0.27451 0.235294
                  roughness 1
                  metalness 0.3
                }
                geometry Cylinder {
                  height 0.01
                  radius 0.03
                }
              }
            ]
          }
        ]
        name "left wheel "
        boundingObject USE wheel
        physics Physics {
        }
      }
    }
    HingeJoint {
      jointParameters HingeJointParameters {
        position 39.57276854035606
        anchor -0.045 0 0.048
      }
      device [
        PositionSensor {
          name "right wheel sensor"
        }
        RotationalMotor {
          name "right_motor"
        }
      ]
      endPoint Solid {
        translation 5.187768511993873e-08 0.04583094541011111 0.062331866841712574
        rotation -0.9999999999997907 6.465777418107757e-07 1.6891738136474196e-08 4.409528609901555
        children [
          DEF wheel Pose {
            translation -0.044992 0 0.048
            rotation 0 1 0 1.57
            children [
              Shape {
                appearance PBRAppearance {
                  baseColor 0.682353 0.27451 0.235294
                  roughness 1
                  metalness 0.3
                }
                geometry Cylinder {
                  height 0.01
                  radius 0.03
                }
              }
            ]
          }
        ]
        name "Right wheel"
        boundingObject USE wheel
        physics Physics {
        }
      }
    }
    DEF bot_body Pose {
      translation 0 0 0.06
      children [
        Shape {
          appearance PBRAppearance {
            baseColor 0.490196 0.101961 0.654902
            roughness 1
            metalness 0
          }
          geometry Cylinder {
            height 0.08
            radius 0.047
          }
        }
      ]
    }
  ]
  boundingObject USE bot_body
  physics Physics {
  }
  controller "obstacle_avoidance_hassan"
}
DEF blue_wall Wall {
  translation 2.88 -0.93 0
  size 0.1 0.2 0.3
  appearance PBRAppearance {
    baseColor 0 0 1
    roughness 1
    metalness 0
  }
}
DEF red_wall Wall {
  translation -0.55 -0.26 0
  name "wall(1)"
  size 0.1 0.2 0.2
  appearance PBRAppearance {
    baseColor 0.666667 0 0
    roughness 1
    metalness 0
  }
}
RobotstadiumSoccerField {
}
